<?xml version="1.0" encoding="utf-8"?>
<!-- This URDF was automatically created by SolidWorks to URDF Exporter! Originally created by Stephen Brawner (brawner@gmail.com) 
     Commit Version: 1.6.0-4-g7f85cfe  Build Version: 1.6.7995.38578
     For more information, please see http://wiki.ros.org/sw_urdf_exporter -->
<robot
  name="g308_km" xmlns:xacro="http://www.ros.org/wiki/xacro">
  <link
    name="base">
    <inertial>
      <origin
        xyz="0.021402 -0.000011 0.005632"
        rpy="0 0 0" />
      <mass
        value="4.135266" />
      <inertia
        ixx="0.022287"
        ixy="0.0"
        ixz="0.0"
        iyy="0.052865"
        iyz="-0.000002"
        izz="0.063659" />
    </inertial>
    <visual>
      <origin
        xyz="0 0 0"
        rpy="0 0 0" />
      <geometry>
        <mesh
          filename="package://g308_km2/meshes/base_link.STL" />
      </geometry>
      <material
        name="">
        <color
          rgba="1 1 0 1" />
      </material>
    </visual>
    <collision>
      <origin
        xyz="0 0 0"
        rpy="0 0 0" />
      <geometry>
        <mesh
          filename="package://g308_km2/meshes/base_link.STL" />
      </geometry>
    </collision>
  </link>
  <!-- <joint
    name="RR_hip_joint"
    type="revolute">
    <origin
      xyz="-0.12709 -0.0615 0.0077356"
      rpy="0 0 0" />
    <parent
      link="base" />
    <child
      link="RR_hip" />
    <axis
      xyz="1 0 0" />
    <limit
      lower="0"
      upper="0"
      effort="20"
      velocity="10" />
  </joint> -->
  <link
    name="FL_hip">
    <inertial>
      <origin
        xyz="0.044862 0.000111 0.000121"
        rpy="0 0 0" />
      <mass
        value="1.000402" />
      <inertia
        ixx="0.000641"
        ixy="-0.000002"
        ixz="0.000002"
        iyy="0.001658"
        iyz="0.0"
        izz="0.001399" />
    </inertial>
    <visual>
      <origin
        xyz="0 0 0"
        rpy="0 0 0" />
      <geometry>
        <mesh
          filename="package://g308_km2/meshes/FL_hip.STL" />
      </geometry>
      <material
        name="">
        <color
          rgba="0.00784313725490196 0.23921568627451 0.823529411764706 1" />
      </material>
    </visual>
    <collision>
      <origin
        xyz="0 0 0"
        rpy="0 0 0" />
      <geometry>
        <mesh
          filename="package://g308_km2/meshes/FL_hip.STL" />
      </geometry>
    </collision>
  </link>
  <joint
    name="FL_hip_joint"
    type="revolute">
    <origin
      xyz="0.169896957635188 0.0614999999999988 0.00773563134770043"
      rpy="0 0 0" />
    <parent
      link="base" />
    <child
      link="FL_hip" />
    <axis
      xyz="1 0 0" />
    <limit
      lower="-0.25"
      upper="0.25"
      effort="20"
      velocity="10" />
  </joint>
  <link
    name="FL_thigh">
    <inertial>
      <origin
        xyz="-0.002626 0.041377 -0.026580"
        rpy="0 0 0" />
      <mass
        value="1.657182" />
      <inertia
        ixx="0.007409"
        ixy="0.000182"
        ixz="-0.000733"
        iyy="0.007405"
        iyz="0.001031"
        izz="0.002280" />
    </inertial>
    <visual>
      <origin
        xyz="0 0 0"
        rpy="0 0 0" />
      <geometry>
        <mesh
          filename="package://g308_km2/meshes/FL_thigh.STL" />
      </geometry>
      <material
        name="">
        <color
          rgba="1 1 0 1" />
      </material>
    </visual>
    <collision>
      <origin
        xyz="0 0 0"
        rpy="0 0 0" />
      <geometry>
        <mesh
          filename="package://g308_km2/meshes/FL_thigh.STL" />
      </geometry>
    </collision>
  </link>
  <joint
    name="FL_thigh_joint"
    type="revolute">
    <origin
      xyz="0.0677000000000165 0.0389999999999984 0"
      rpy="0 0 0" />
    <parent
      link="FL_hip" />
    <child
      link="FL_thigh" />
    <axis
      xyz="0 1 0" />
    <limit
      lower="-1.5"
      upper="1.5"
      effort="20"
      velocity="10" />
  </joint>
  <link
    name="FL_calf">
    <inertial>
      <origin
        xyz="0.0502864361062866 -0.0100012628542901 -0.0913683307386556"
        rpy="0 0 0" />
      <mass
        value="0.24357427073011" />
      <inertia
        ixx="0.001367"
        ixy="0.0"
        ixz="0.000642"
        iyy="0.001698"
        iyz="0.0"
        izz="0.000356" />
    </inertial>
    <visual>
      <origin
        xyz="0 0 0"
        rpy="0 0 0" />
      <geometry>
        <mesh
          filename="package://g308_km2/meshes/FL_calf.STL" />
      </geometry>
      <material
        name="">
        <color
          rgba="1 1 0 1" />
      </material>
    </visual>
    <collision>
      <origin
        xyz="0 0 0"
        rpy="0 0 0" />
      <geometry>
        <mesh
          filename="package://g308_km2/meshes/FL_calf.STL" />
      </geometry>
    </collision>
  </link>
  <joint
    name="FL_calf_joint"
    type="revolute">
    <origin
      xyz="0 0.0765000024826573 -0.22000000617793"
      rpy="0 0 0" />
    <parent
      link="FL_thigh" />
    <child
      link="FL_calf" />
    <axis
      xyz="0 1 0" />
    <limit
      lower="-2.3"
      upper="0"
      effort="20"
      velocity="10" />
  </joint>
  <link
    name="FL_foot">
    <inertial>
      <origin
        xyz="-0.000006 0.0 -9.21846519300606E-05"
        rpy="0 0 0" />
      <mass
        value="0.0311902243903798" />
      <inertia
        ixx="5.01347937484814E-06"
        ixy="-8.23952528788361E-13"
        ixz="-1.58989737485414E-08"
        iyy="5.06120841117782E-06"
        iyz="-1.84888830000075E-13"
        izz="4.99040323981824E-06" />
    </inertial>
    <visual>
      <origin
        xyz="0 0 0"
        rpy="0 0 0" />
      <geometry>
        <mesh
          filename="package://g308_km2/meshes/FL_foot.STL" />
      </geometry>
      <material
        name="">
        <color
          rgba="1 1 1 1" />
      </material>
    </visual>
    <collision>
      <origin
        xyz="0 0 0"
        rpy="0 0 0" />
      <geometry>
        <mesh
          filename="package://g308_km2/meshes/FL_foot.STL" />
      </geometry>
    </collision>
  </link>
  <joint
    name="FL_foot_joint"
    type="fixed">
    <origin
      xyz="0.0961788196628297 -0.00999999474772562 -0.224142335649936"
      rpy="0 0 0" />
    <parent
      link="FL_calf" />
    <child
      link="FL_foot" />
    <axis
      xyz="0 0 0" />
    <limit
      effort="20"
      velocity="10" />
  </joint>
  <link
    name="RL_hip">
    <inertial>
      <origin
        xyz="-0.044862 0.000111 0.000055"
        rpy="0 0 0" />
      <mass
        value="1.000402" />
      <inertia
        ixx="0.000641"
        ixy="0.000001"
        ixz="-0.000004"
        iyy="0.001658"
        iyz="0.0"
        izz="0.001399" />
    </inertial>
    <visual>
      <origin
        xyz="0 0 0"
        rpy="0 0 0" />
      <geometry>
        <mesh
          filename="package://g308_km2/meshes/RL_hip.STL" />
      </geometry>
      <material
        name="">
        <color
          rgba="0.00784313725490196 0.23921568627451 0.823529411764706 1" />
      </material>
    </visual>
    <collision>
      <origin
        xyz="0 0 0"
        rpy="0 0 0" />
      <geometry>
        <mesh
          filename="package://g308_km2/meshes/RL_hip.STL" />
      </geometry>
    </collision>
  </link>
  <joint
    name="RL_hip_joint"
    type="revolute">
    <origin
      xyz="-0.127094802324013 0.0615000000000004 0.00773563134769126"
      rpy="0 0 0" />
    <parent
      link="base" />
    <child
      link="RL_hip" />
    <axis
      xyz="1 0 0" />
    <limit
      lower="-0.25"
      upper="0.25"
      effort="20"
      velocity="10" />
  </joint>
  <link
    name="RL_thigh">
    <inertial>
      <origin
        xyz="-0.014268 0.021377 -0.014939"
        rpy="0 0 0" />
      <mass
        value="1.657182" />
      <inertia
        ixx="0.007409"
        ixy="0.000182"
        ixz="-0.000733"
        iyy="0.007405"
        iyz="0.001031"
        izz="0.002280" />
    </inertial>
    <visual>
      <origin
        xyz="0 0 0"
        rpy="0 0 0" />
      <geometry>
        <mesh
          filename="package://g308_km2/meshes/RL_thigh.STL" />
      </geometry>
      <material
        name="">
        <color
          rgba="1 1 0 1" />
      </material>
    </visual>
    <collision>
      <origin
        xyz="0 0 0"
        rpy="0 0 0" />
      <geometry>
        <mesh
          filename="package://g308_km2/meshes/RL_thigh.STL" />
      </geometry>
    </collision>
  </link>
  <joint
    name="RL_thigh_joint"
    type="revolute">
    <origin
      xyz="-0.0560585780326773 0.0590000000000006 -0.0116414219673209"
      rpy="0 0 0" />
    <parent
      link="RL_hip" />
    <child
      link="RL_thigh" />
    <axis
      xyz="0 1 0" />
    <limit
      lower="-1.5"
      upper="1.5"
      effort="20"
      velocity="10" />
  </joint>
  <link
    name="RL_calf">
    <inertial>
      <origin
        xyz="0.0502864229249339 -0.0100012603719431 -0.0913683369164015"
        rpy="0 0 0" />
      <mass
        value="0.243574270730111" />
      <inertia
        ixx="0.001367"
        ixy="0.0"
        ixz="-0.000642"
        iyy="0.001698"
        iyz="0.0"
        izz="0.000356" />
    </inertial>
    <visual>
      <origin
        xyz="0 0 0"
        rpy="0 0 0" />
      <geometry>
        <mesh
          filename="package://g308_km2/meshes/RL_calf.STL" />
      </geometry>
      <material
        name="">
        <color
          rgba="1 1 0 1" />
      </material>
    </visual>
    <collision>
      <origin
        xyz="0 0 0"
        rpy="0 0 0" />
      <geometry>
        <mesh
          filename="package://g308_km2/meshes/RL_calf.STL" />
      </geometry>
    </collision>
  </link>
  <joint
    name="RL_calf_joint"
    type="revolute">
    <origin
      xyz="-0.0116414219673151 0.0565000000000057 -0.208358578032676"
      rpy="0 0 0" />
    <parent
      link="RL_thigh" />
    <child
      link="RL_calf" />
    <axis
      xyz="0 1 0" />
    <limit
      lower="-2.3"
      upper="0"
      effort="20"
      velocity="10" />
  </joint>
  <link
    name="RL_foot">
    <inertial>
      <origin
        xyz="-5.85322688909096E-06 2.61542565382911E-10 -9.2190868305364E-05"
        rpy="0 0 0" />
      <mass
        value="0.0311902243903798" />
      <inertia
        ixx="5.01347937484815E-06"
        ixy="-8.23952529291106E-13"
        ixz="-1.58989737485399E-08"
        iyy="5.06120841117782E-06"
        iyz="-1.8488882759212E-13"
        izz="4.99040323981824E-06" />
    </inertial>
    <visual>
      <origin
        xyz="0 0 0"
        rpy="0 0 0" />
      <geometry>
        <mesh
          filename="package://g308_km2/meshes/RL_foot.STL" />
      </geometry>
      <material
        name="">
        <color
          rgba="1 1 1 1" />
      </material>
    </visual>
    <collision>
      <origin
        xyz="0 0 0"
        rpy="0 0 0" />
      <geometry>
        <mesh
          filename="package://g308_km2/meshes/RL_foot.STL" />
      </geometry>
    </collision>
  </link>
  <joint
    name="RL_foot_joint"
    type="fixed">
    <origin
      xyz="0.0961788196898257 -0.00999999468162976 -0.224142335611317"
      rpy="0 0 0" />
    <parent
      link="RL_calf" />
    <child
      link="RL_foot" />
    <axis
      xyz="0 0 0" />
  </joint>
  <link
    name="FR_hip">
    <inertial>
      <origin
        xyz="0.044862 -0.000111 0.000055"
        rpy="0 0 0" />
      <mass
        value="1.000402" />
      <inertia
        ixx="0.000641"
        ixy="0.000001"
        ixz="0.000004"
        iyy="0.001658"
        iyz="0.0"
        izz="0.001399" />
    </inertial>
    <visual>
      <origin
        xyz="0 0 0"
        rpy="0 0 0" />
      <geometry>
        <mesh
          filename="package://g308_km2/meshes/FR_hip.STL" />
      </geometry>
      <material
        name="">
        <color
          rgba="0.00784313725490196 0.23921568627451 0.823529411764706 1" />
      </material>
    </visual>
    <collision>
      <origin
        xyz="0 0 0"
        rpy="0 0 0" />
      <geometry>
        <mesh
          filename="package://g308_km2/meshes/FR_hip.STL" />
      </geometry>
    </collision>
  </link>
  <joint
    name="FR_hip_joint"
    type="revolute">
    <origin
      xyz="0.169896957585034 -0.0615000000501541 0.00773564344453465"
      rpy="0 0 0" />
    <parent
      link="base" />
    <child
      link="FR_hip" />
    <axis
      xyz="1 0 0" />
    <limit
      lower="-0.25"
      upper="0.25"
      effort="20"
      velocity="10" />
  </joint>
  <link
    name="FR_thigh">
    <inertial>
      <origin
        xyz="-0.014239 0.021377 -0.014910"
        rpy="0 0 0" />
      <mass
        value="1.657182" />
      <inertia
        ixx="0.007412"
        ixy="-0.000183"
        ixz="-0.000734"
        iyy="0.007408"
        iyz="-0.001032"
        izz="0.002281" />
    </inertial>
    <visual>
      <origin
        xyz="0 0 0"
        rpy="0 0 0" />
      <geometry>
        <mesh
          filename="package://g308_km2/meshes/FR_thigh.STL" />
      </geometry>
      <material
        name="">
        <color
          rgba="1 1 0 1" />
      </material>
    </visual>
    <collision>
      <origin
        xyz="0 0 0"
        rpy="0 0 0" />
      <geometry>
        <mesh
          filename="package://g308_km2/meshes/FR_thigh.STL" />
      </geometry>
    </collision>
  </link>
  <joint
    name="FR_thigh_joint"
    type="revolute">
    <origin
      xyz="0.0793414219628311 -0.0590000000044883 -0.0116414499397221"
      rpy="0 0 0" />
    <parent
      link="FR_hip" />
    <child
      link="FR_thigh" />
    <axis
      xyz="0 1 0" />
    <limit
      lower="-1.5"
      upper="1.5"
      effort="20"
      velocity="10" />
  </joint>
  <link
    name="FR_calf">
    <inertial>
      <origin
        xyz="0.0502864229249339 -0.0100012603719431 -0.0913683369164015"
        rpy="0 0 0" />
      <mass
        value="0.243574270730111" />
      <inertia
        ixx="0.001367"
        ixy="0.0"
        ixz="0.000642"
        iyy="0.001698"
        iyz="0.0"
        izz="0.000356" />
    </inertial>
    <visual>
      <origin
        xyz="0 0 0"
        rpy="0 0 0" />
      <geometry>
        <mesh
          filename="package://g308_km2/meshes/FR_calf.STL" />
      </geometry>
      <material
        name="">
        <color
          rgba="1 1 0 1" />
      </material>
    </visual>
    <collision>
      <origin
        xyz="0 0 0"
        rpy="0 0 0" />
      <geometry>
        <mesh
          filename="package://g308_km2/meshes/FR_calf.STL" />
      </geometry>
    </collision>
  </link>
  <joint
    name="FR_calf_joint"
    type="revolute">
    <origin
      xyz="-0.0116414038818166 -0.0365000120545385 -0.208358576391672"
      rpy="0 0 0" />
    <parent
      link="FR_thigh" />
    <child
      link="FR_calf" />
    <axis
      xyz="0 1 0" />
    <limit
      lower="-2.3"
      upper="0"
      effort="20"
      velocity="10" />
  </joint>
  <link
    name="FR_foot">
    <inertial>
      <origin
        xyz="-5.85322568097402E-06 2.64939459260205E-10 -9.21908797132942E-05"
        rpy="0 0 0" />
      <mass
        value="0.0311902243903797" />
      <inertia
        ixx="5.01347937484811E-06"
        ixy="-8.23952528235531E-13"
        ixz="-1.58989737485516E-08"
        iyy="5.06120841117781E-06"
        iyz="-1.84888823216108E-13"
        izz="4.99040323981825E-06" />
    </inertial>
    <visual>
      <origin
        xyz="0 0 0"
        rpy="0 0 0" />
      <geometry>
        <mesh
          filename="package://g308_km2/meshes/FR_foot.STL" />
      </geometry>
      <material
        name="">
        <color
          rgba="1 1 1 1" />
      </material>
    </visual>
    <collision>
      <origin
        xyz="0 0 0"
        rpy="0 0 0" />
      <geometry>
        <mesh
          filename="package://g308_km2/meshes/FR_foot.STL" />
      </geometry>
    </collision>
  </link>
  <joint
    name="FR_foot_joint"
    type="fixed" dont_collapse="true">
    <origin
      xyz="0.096178801658822 -0.00999998257200752 -0.224142321376693"
      rpy="0 0 0" />
    <parent
      link="FR_calf" />
    <child
      link="FR_foot" />
    <axis
      xyz="0 0 0" />
  </joint>
  <link
    name="RR_hip">
    <inertial>
      <origin
        xyz="-0.044862 -0.000111 0.000121"
        rpy="0 0 0" />
      <mass
        value="1.000402" />
      <inertia
        ixx="0.000641"
        ixy="-0.000002"
        ixz="-0.000002"
        iyy="0.001658"
        iyz="0.0"
        izz="0.001399" />
    </inertial>
    <visual>
      <origin
        xyz="0 0 0"
        rpy="0 0 0" />
      <geometry>
        <mesh
          filename="package://g308_km2/meshes/RR_hip.STL" />
      </geometry>
      <material
        name="">
        <color
          rgba="0.00784313725490196 0.23921568627451 0.823529411764706 1" />
      </material>
    </visual>
    <collision>
      <origin
        xyz="0 0 0"
        rpy="0 0 0" />
      <geometry>
        <mesh
          filename="package://g308_km2/meshes/RR_hip.STL" />
      </geometry>
    </collision>
  </link>
  <joint
    name="RR_hip_joint"
    type="revolute">
    <origin
      xyz="-0.127094802324014 -0.0614999999999988 0.00773563134771131"
      rpy="0 0 0" />
    <parent
      link="base" />
    <child
      link="RR_hip" />
    <axis
      xyz="1 0 0" />
    <limit
      lower="-0.25"
      upper="0.25"
      effort="20"
      velocity="10" />
  </joint>
  <link
    name="RR_thigh">
    <inertial>
      <origin
        xyz="-0.014239 -0.021377 -0.014910"
        rpy="0 0 0" />
      <mass
        value="1.657182" />
      <inertia
        ixx="0.007412"
        ixy="-0.000183"
        ixz="-0.000734"
        iyy="0.007408"
        iyz="-0.001032"
        izz="0.002281" />
    </inertial>
    <visual>
      <origin
        xyz="0 0 0"
        rpy="0 0 0" />
      <geometry>
        <mesh
          filename="package://g308_km2/meshes/RR_thigh.STL" />
      </geometry>
      <material
        name="">
        <color
          rgba="1 1 0 1" />
      </material>
    </visual>
    <collision>
      <origin
        xyz="0 0 0"
        rpy="0 0 0" />
      <geometry>
        <mesh
          filename="package://g308_km2/meshes/RR_thigh.STL" />
      </geometry>
    </collision>
  </link>
  <joint
    name="RR_thigh_joint"
    type="revolute">
    <origin
      xyz="-0.0560585780326786 -0.0589999999999984 -0.0116414219673416"
      rpy="0 0 0" />
    <parent
      link="RR_hip" />
    <child
      link="RR_thigh" />
    <axis
      xyz="0 1 0" />
    <limit
      lower="-1.5"
      upper="1.5"
      effort="20"
      velocity="10" />
  </joint>
  <link
    name="RR_calf">
    <inertial>
      <origin
        xyz="0.0502864229249339 -0.0100012603719431 -0.0913683369164015"
        rpy="0 0 0" />
      <mass
        value="0.243574270730111" />
      <inertia
        ixx="0.001367"
        ixy="0.0"
        ixz="0.000642"
        iyy="0.001698"
        iyz="0.0"
        izz="0.000356" />
    </inertial>
    <visual>
      <origin
        xyz="0 0 0"
        rpy="0 0 0" />
      <geometry>
        <mesh
          filename="package://g308_km2/meshes/RR_calf.STL" />
      </geometry>
      <material
        name="">
        <color
          rgba="1 1 0 1" />
      </material>
    </visual>
    <collision>
      <origin
        xyz="0 0 0"
        rpy="0 0 0" />
      <geometry>
        <mesh
          filename="package://g308_km2/meshes/RR_calf.STL" />
      </geometry>
    </collision>
  </link>
  <joint
    name="RR_calf_joint"
    type="revolute">
    <origin
      xyz="-0.0116414073695187 -0.0365000163770425 -0.208358573653802"
      rpy="0 0 0" />
    <parent
      link="RR_thigh" />
    <child
      link="RR_calf" />
    <axis
      xyz="0 1 0" />
    <limit
      lower="-2.3"
      upper="0"
      effort="20"
      velocity="10" />
  </joint>
  <link
    name="RR_foot">
    <inertial>
      <origin
        xyz="-5.85322945402533E-06 2.69323785495601E-10 -9.21908810186389E-05"
        rpy="0 0 0" />
      <mass
        value="0.0311902243903798" />
      <inertia
        ixx="5.01347937484812E-06"
        ixy="-8.2395252888934E-13"
        ixz="-1.58989737485532E-08"
        iyy="5.06120841117781E-06"
        iyz="-1.84888826512745E-13"
        izz="4.99040323981825E-06" />
    </inertial>
    <visual>
      <origin
        xyz="0 0 0"
        rpy="0 0 0" />
      <geometry>
        <mesh
          filename="package://g308_km2/meshes/RR_foot.STL" />
      </geometry>
      <material
        name="">
        <color
          rgba="1 1 1 1" />
      </material>
    </visual>
    <collision>
      <origin
        xyz="0 0 0"
        rpy="0 0 0" />
      <geometry>
        <mesh
          filename="package://g308_km2/meshes/RR_foot.STL" />
      </geometry>
    </collision>
  </link>
  <joint
    name="RR_foot_joint"
    type="fixed">
    <origin
      xyz="0.0961788050922009 -0.0099999783045851 -0.224142339990188"
      rpy="0 0 0" />
    <parent
      link="RR_calf" />
    <child
      link="RR_foot" />
    <axis
      xyz="0 0 0" />
  </joint>
    <transmission name="t11">
    <type>transmission_interface/SimpleTransmission</type>
    <joint name="FL_hip_joint">
      <hardwareInterface>hardware_interface/EffortJointInterface</hardwareInterface>
    </joint>
    <actuator name="a11">
      <mechanicalReduction>1.0</mechanicalReduction>
      <hardwareInterface>hardware_interface/EffortJointInterface</hardwareInterface>
    </actuator>
  </transmission>
   <transmission name="t12">
    <type>transmission_interface/SimpleTransmission</type>
    <joint name="FL_thigh_joint">
      <hardwareInterface>hardware_interface/EffortJointInterface</hardwareInterface>
    </joint>
    <actuator name="a12">
      <mechanicalReduction>1.0</mechanicalReduction>
      <hardwareInterface>hardware_interface/EffortJointInterface</hardwareInterface>
    </actuator>
  </transmission>
   <transmission name="t13">
    <type>transmission_interface/SimpleTransmission</type>
    <joint name="FL_calf_joint">
      <hardwareInterface>hardware_interface/EffortJointInterface</hardwareInterface>
    </joint>
    <actuator name="a13">
      <mechanicalReduction>1.0</mechanicalReduction>
      <hardwareInterface>hardware_interface/EffortJointInterface</hardwareInterface>
    </actuator>
  </transmission>
  <transmission name="t21">
    <type>transmission_interface/SimpleTransmission</type>
    <joint name="RL_hip_joint">
      <hardwareInterface>hardware_interface/EffortJointInterface</hardwareInterface>
    </joint>
    <actuator name="a21">
      <mechanicalReduction>1.0</mechanicalReduction>
      <hardwareInterface>hardware_interface/EffortJointInterface</hardwareInterface>
    </actuator>
  </transmission>
   <transmission name="t22">
    <type>transmission_interface/SimpleTransmission</type>
    <joint name="RL_thigh_joint">
      <hardwareInterface>hardware_interface/EffortJointInterface</hardwareInterface>
    </joint>
    <actuator name="a21">
      <mechanicalReduction>1.0</mechanicalReduction>
      <hardwareInterface>hardware_interface/EffortJointInterface</hardwareInterface>
    </actuator>
  </transmission>
   <transmission name="t23">
    <type>transmission_interface/SimpleTransmission</type>
    <joint name="RL_calf_joint">
      <hardwareInterface>hardware_interface/EffortJointInterface</hardwareInterface>
    </joint>
    <actuator name="a23">
      <mechanicalReduction>1.0</mechanicalReduction>
      <hardwareInterface>hardware_interface/EffortJointInterface</hardwareInterface>
    </actuator>
  </transmission>
   <transmission name="t31">
    <type>transmission_interface/SimpleTransmission</type>
    <joint name="FR_hip_joint">
      <hardwareInterface>hardware_interface/EffortJointInterface</hardwareInterface>
    </joint>
    <actuator name="a31">
      <mechanicalReduction>1.0</mechanicalReduction>
      <hardwareInterface>hardware_interface/EffortJointInterface</hardwareInterface>
    </actuator>
  </transmission>
   <transmission name="t32">
    <type>transmission_interface/SimpleTransmission</type>
    <joint name="FR_thigh_joint">
      <hardwareInterface>hardware_interface/EffortJointInterface</hardwareInterface>
    </joint>
    <actuator name="a32">
      <mechanicalReduction>1.0</mechanicalReduction>
      <hardwareInterface>hardware_interface/EffortJointInterface</hardwareInterface>
    </actuator>
  </transmission>
   <transmission name="t32">
    <type>transmission_interface/SimpleTransmission</type>
    <joint name="FR_calf_joint">
      <hardwareInterface>hardware_interface/EffortJointInterface</hardwareInterface>
    </joint>
    <actuator name="a32">
      <mechanicalReduction>1.0</mechanicalReduction>
      <hardwareInterface>hardware_interface/EffortJointInterface</hardwareInterface>
    </actuator>
  </transmission>
   <transmission name="t41">
    <type>transmission_interface/SimpleTransmission</type>
    <joint name="RR_hip_joint">
      <hardwareInterface>hardware_interface/EffortJointInterface</hardwareInterface>
    </joint>
    <actuator name="a41">
      <mechanicalReduction>1.0</mechanicalReduction>
      <hardwareInterface>hardware_interface/EffortJointInterface</hardwareInterface>
    </actuator>
  </transmission>
   <transmission name="t42">
    <type>transmission_interface/SimpleTransmission</type>
    <joint name="RR_thigh_joint">
      <hardwareInterface>hardware_interface/EffortJointInterface</hardwareInterface>
    </joint>
    <actuator name="a42">
      <mechanicalReduction>1.0</mechanicalReduction>
      <hardwareInterface>hardware_interface/EffortJointInterface</hardwareInterface>
    </actuator>
  </transmission>
   <transmission name="t43">
    <type>transmission_interface/SimpleTransmission</type>
    <joint name="RR_calf_joint">
      <hardwareInterface>hardware_interface/EffortJointInterface</hardwareInterface>
    </joint>
    <actuator name="a43">
      <mechanicalReduction>1.0</mechanicalReduction>
      <hardwareInterface>hardware_interface/EffortJointInterface</hardwareInterface>
    </actuator>
  </transmission>
  <gazebo>
    <plugin name="gazebo_ros_control" filename="libgazebo_ros_control.so">
      <robotNamespace>/horse</robotNamespace>
      <robotSimType>gazebo_ros_control/DefaultRobotHWSim</robotSimType>
      <legacyModeNS>true</legacyModeNS>
    </plugin>
  </gazebo>
  <!-- <gazebo reference="base">
    <kp>1000000.0</kp> 
    <kd>1.0</kd>
    <mu1>0.2</mu1>
    <mu2>0.2</mu2>
  </gazebo>

  <gazebo reference="RR_foot">
    <kp>1000000.0</kp> 
    <kd>1.0</kd>
    <mu1>0.6</mu1>
    <mu2>0.6</mu2>
    <minDepth>0.001</minDepth>
  </gazebo>

  <gazebo reference="FR_foot">
    <kp>1000000.0</kp> 
    <kd>1.0</kd>
    <mu1>0.6</mu1>
    <mu2>0.6</mu2>
    <minDepth>0.001</minDepth>
    <self_collide>1</self_collide>
  </gazebo>

  <gazebo reference="FR_calf">
    <mu1>0.2</mu1>
    <mu2>0.2</mu2>
    <self_collide>1</self_collide>
  </gazebo>

  <gazebo reference="FL_foot">
    <kp>1000000.0</kp> 
    <kd>1.0</kd>
    <mu1>0.6</mu1>
    <mu2>0.6</mu2>
    <minDepth>0.001</minDepth>
  </gazebo>

  <gazebo reference="RL_foot">
    <kp>1000000.0</kp> 
    <kd>1.0</kd>
    <mu1>0.6</mu1>
    <mu2>0.6</mu2>
    <minDepth>0.001</minDepth>
  </gazebo> -->

  <gazebo reference="base">
      <turnGravityOff>false</turnGravityOff>
  </gazebo>

  <gazebo reference="imu_link">
      <mu1>0.2</mu1>
      <mu2>0.2</mu2>
  </gazebo>

  <!-- FL leg -->
  <gazebo reference="FL_hip">
      <mu1>0.2</mu1>
      <mu2>0.2</mu2>

  </gazebo>
  <gazebo reference="FL_thigh">
      <mu1>0.2</mu1>
      <mu2>0.2</mu2>
      <self_collide>1</self_collide>
      <kp  value="1000000.0"/>
      <kd  value="1.0"/>
  </gazebo>
  <gazebo reference="FL_calf">
      <mu1>0.2</mu1>
      <mu2>0.2</mu2>
      <self_collide>1</self_collide>
  </gazebo>
  <gazebo reference="FL_foot">
      <mu1>0.6</mu1>
      <mu2>0.6</mu2>
      <self_collide>1</self_collide>
      <kp  value="1000000.0"/>
      <kd  value="1.0"/>
  </gazebo>

  <!-- FR leg -->
  <gazebo reference="FR_hip">
      <mu1>0.2</mu1>
      <mu2>0.2</mu2>
  </gazebo>
  <gazebo reference="FR_thigh">
      <mu1>0.2</mu1>
      <mu2>0.2</mu2>
      <self_collide>1</self_collide>
      <kp  value="1000000.0"/>
      <kd  value="1.0"/>
  </gazebo>
  <gazebo reference="FR_calf">
      <mu1>0.2</mu1>
      <mu2>0.2</mu2>
      <self_collide>1</self_collide>
  </gazebo>
  <gazebo reference="FR_foot">
      <mu1>0.6</mu1>
      <mu2>0.6</mu2>
      <self_collide>1</self_collide>
      <kp  value="1000000.0"/>
      <kd  value="1.0"/>
  </gazebo>

  <!-- RL leg -->
  <gazebo reference="RL_hip">
      <mu1>0.2</mu1>
      <mu2>0.2</mu2>
  </gazebo>
  <gazebo reference="RL_thigh">
      <mu1>0.2</mu1>
      <mu2>0.2</mu2>
      <self_collide>1</self_collide>
      <kp  value="1000000.0"/>
      <kd  value="1.0"/>
  </gazebo>
  <gazebo reference="RL_calf">
      <mu1>0.2</mu1>
      <mu2>0.2</mu2>
      <self_collide>1</self_collide>
  </gazebo>
  <gazebo reference="RL_foot">
      <mu1>0.6</mu1>
      <mu2>0.6</mu2>
      <self_collide>1</self_collide>
      <kp  value="1000000.0"/>
      <kd  value="1.0"/>
  </gazebo>

  <!-- RR leg -->
  <gazebo reference="RR_hip">
      <mu1>0.2</mu1>
      <mu2>0.2</mu2>
  </gazebo>
  <gazebo reference="RR_thigh">
      <mu1>0.2</mu1>
      <mu2>0.2</mu2>
      <self_collide>1</self_collide>
      <kp  value="1000000.0"/>
      <kd  value="1.0"/>
  </gazebo>
  <gazebo reference="RR_calf">
      <mu1>0.2</mu1>
      <mu2>0.2</mu2>
      <self_collide>1</self_collide>
  </gazebo>
  <gazebo reference="RR_foot">
      <mu1>0.6</mu1>
      <mu2>0.6</mu2>
      <self_collide>1</self_collide>
      <kp  value="1000000.0"/>
      <kd  value="1.0"/>
  </gazebo>
  <gazebo>
      <plugin name="3dplot" filename="libLinkPlot3DPlugin.so">
          <frequency>10</frequency>
          <plot>
              <link>base</link>
              <pose>0 0 0 0 0 0</pose>
              <material>Gazebo/Yellow</material>
          </plot>
      </plugin>
  </gazebo>

      <joint name="imu_joint" type="fixed">
        <parent link="base"/>
        <child link="imu_link"/>
        <origin rpy="0 0 0" xyz="0 0 0"/>
    </joint>

    <link name="imu_link">
        <inertial>
            <mass value="0.001"/>
            <origin rpy="0 0 0" xyz="0 0 0"/>
            <inertia ixx="0.0001" ixy="0" ixz="0" iyy="0.0001" iyz="0" izz="0.0001"/>
        </inertial>
        <visual>
            <origin rpy="0 0 0" xyz="0 0 0"/>
            <geometry>
                <box size="0.001 0.001 0.001"/>
            </geometry>
            <material name="red"/>
        </visual>
        <collision>
            <origin rpy="0 0 0" xyz="0 0 0"/>
            <geometry>
                <box size=".001 .001 .001"/>
            </geometry>
        </collision>
    </link>

        <gazebo reference="imu_link">
        <gravity>true</gravity>
        <sensor name="imu_sensor" type="imu">
            <always_on>true</always_on>
            <update_rate>1000</update_rate>
            <visualize>true</visualize>
            <topic>__default_topic__</topic>
            <plugin filename="libgazebo_ros_imu_sensor.so" name="imu_plugin">
                <topicName>base_imu</topicName>
                <bodyName>imu_link</bodyName>
                <updateRateHZ>1000.0</updateRateHZ>
                <gaussianNoise>0.0</gaussianNoise>
                <xyzOffset>0 0 0</xyzOffset>
                <rpyOffset>0 0 0</rpyOffset>
                <frameName>imu_link</frameName>
            </plugin>
            <pose>0 0 0 0 0 0</pose>
        </sensor>
    </gazebo>

  
  <!-- <gazebo reference="RR_foot">
    <material>Gazebo/Red</material>
    <mu1 value="10.0"/>
    <mu2 value="10.0"/>
    <kp value="0.3" />
    <kd value="1.0" />
    <fdir1 value="1 0 0"/>
    <gravity value="true"/>
  </gazebo> -->
  
   <gazebo 
      reference="RR_foot_joint">
     <provideFeedback>true</provideFeedback>
     <disableFixedJointLumping>false</disableFixedJointLumping>
   </gazebo>
  
  <!-- <gazebo>
    <plugin name="ft_sensor" filename="libgazebo_ros_ft_sensor.so">
      <updateRate>100.0</updateRate>
      <topicName>RR_contact</topicName>
      <jointName>RR_foot_joint</jointName>
      <frameName>imu_link</frameName> 
    </plugin>
  </gazebo> -->

  <gazebo 
      reference="RL_foot_joint">
     <provideFeedback>true</provideFeedback>
     <disableFixedJointLumping>false</disableFixedJointLumping>
  </gazebo>
  
  <!-- <gazebo>
    <plugin name="ft_sensor" filename="libgazebo_ros_ft_sensor.so">
      <updateRate>100.0</updateRate>
      <topicName>RL_contact</topicName>
      <jointName>RL_foot_joint</jointName>
      <frameName>imu_link</frameName>
    </plugin>
  </gazebo> -->

     <gazebo 
      reference="FL_foot_joint">
     <provideFeedback>true</provideFeedback>
     <disableFixedJointLumping>false</disableFixedJointLumping>
   </gazebo>
  
  <!-- <gazebo>
    <plugin name="ft_sensor" filename="libgazebo_ros_ft_sensor.so">
      <updateRate>100.0</updateRate>
      <topicName>FL_contact</topicName>
      <jointName>FL_foot_joint</jointName>
      <frameName>imu_link</frameName>
    </plugin>
  </gazebo> -->

     <gazebo 
      reference="FR_foot_joint">
     <provideFeedback>true</provideFeedback>
     <disableFixedJointLumping>false</disableFixedJointLumping>
   </gazebo>
<!--   
  <gazebo>
    <plugin name="ft_sensor" filename="libgazebo_ros_ft_sensor.so">
      <updateRate>100.0</updateRate>
      <topicName>FR_contact</topicName>
      <jointName>FR_foot_joint</jointName>
      <frameName>imu_link</frameName>
    </plugin>
  </gazebo> -->
    <gazebo reference="FR_calf">
      <sensor name="FR_foot" type="contact">
      <update_rate>100</update_rate>
      <plugin name="contactPlugin" filename="libunitreeFootContactPlugin.so"/>
        <frame_id>FR_foot</frame_id>
      <contact>
          <!-- <collision>FR_calf_fixed_joint_lump__FR_foot_collision_1</collision> -->
          <collision>FR_calf_fixed_joint_lump__FR_foot_collision_1</collision>
      </contact>
      </sensor>
    </gazebo>

    <gazebo reference="FR_foot">
        <visual>
            <plugin name="drawForcePlugin" filename="libunitreeDrawForcePlugin.so">
                <topicName>FR_foot_contact</topicName>
            </plugin>
        </visual>
    </gazebo>

    <gazebo reference="FL_calf">
      <sensor name="FL_foot" type="contact">
      <update_rate>100</update_rate>
      <plugin name="contactPlugin" filename="libunitreeFootContactPlugin.so"/>
        <frame_id>FL_foot</frame_id>
      <contact>
          <!-- <collision>FR_calf_fixed_joint_lump__FR_foot_collision_1</collision> -->
          <collision>FL_calf_fixed_joint_lump__FL_foot_collision_1</collision>
      </contact>
      </sensor>
    </gazebo>

    <gazebo reference="FL_foot">
        <visual>
            <plugin name="drawForcePlugin" filename="libunitreeDrawForcePlugin.so">
                <topicName>FL_foot_contact</topicName>
            </plugin>
        </visual>
    </gazebo>

    <gazebo reference="RL_calf">
      <sensor name="RL_foot" type="contact">
      <update_rate>100</update_rate>
      <plugin name="contactPlugin" filename="libunitreeFootContactPlugin.so"/>
        <frame_id>RL_foot</frame_id>
      <contact>
          <!-- <collision>FR_calf_fixed_joint_lump__FR_foot_collision_1</collision> -->
          <collision>RL_calf_fixed_joint_lump__RL_foot_collision_1</collision>
      </contact>
      </sensor>
    </gazebo>

    <gazebo reference="RL_foot">
        <visual>
            <plugin name="drawForcePlugin" filename="libunitreeDrawForcePlugin.so">
                <topicName>RL_foot_contact</topicName>
            </plugin>
        </visual>
    </gazebo>

    <gazebo reference="RR_calf">
      <sensor name="RR_foot" type="contact">
      <update_rate>100</update_rate>
      <plugin name="contactPlugin" filename="libunitreeFootContactPlugin.so"/>
        <frame_id>RR_foot</frame_id>
      <contact>
          <!-- <collision>FR_calf_fixed_joint_lump__FR_foot_collision_1</collision> -->
          <collision>RR_calf_fixed_joint_lump__RR_foot_collision_1</collision>
      </contact>
      </sensor>
    </gazebo>

    <gazebo reference="RR_foot">
        <visual>
            <plugin name="drawForcePlugin" filename="libunitreeDrawForcePlugin.so">
                <topicName>RR_foot_contact</topicName>
            </plugin>
        </visual>
    </gazebo>

  <!-- <gazebo reference="FR_foot">
    <visual>
        <plugin name="drawForcePlugin" filename="libunitreeDrawForcePlugin.so">
            <topicName>FR_foot_contact</topicName>
        </plugin>
    </visual>
  </gazebo> -->

  <!-- <gazebo>
    <plugin filename="libgazebo_ros_force.so" name="gazebo_ros_force">
        <bodyName>base</bodyName>
        <topicName>/apply_force/trunk</topicName>
    </plugin>
  </gazebo> -->

</robot>